<?xml version="1.0"?>
<robot name="kitchen_robot_v3">
  <link name="base_link"/>
  <link name="L_peg">
    <visual>
      <origin xyz="0.000000 0.000000 0.000000" rpy="0.000000 0.000000 0.000000"/>
      <geometry>
        <mesh filename="../L_peg.stl"/>
      </geometry>
      <material name="L_peg_mat">
        <color rgba="1.000 1.000 1.000 1.000"/>
      </material>
    </visual>
    <collision>
      <origin xyz="0.000000 0.000000 0.000000" rpy="0.000000 0.000000 0.000000"/>
      <geometry>
        <mesh filename="../L_peg.stl"/>
      </geometry>
    </collision>
  </link>
  <joint name="joint_L_peg" type="revolute">
    <parent link="base_link"/>
    <child link="L_peg"/>
    <origin xyz="0.000000 0.000000 0.000000" rpy="0.000000 -0.000000 0.000000"/>
    <axis xyz="1.000000 0.000000 0.000000"/>
    <limit lower="-3.141593" upper="3.141593" effort="0.000000" velocity="0.000000"/>
  </joint>
</robot>